Workbook

Sheet README
A1: Semester financial operating model: three-year, driver-based, monthly
A2: STATUS: PLANNING MODEL. Not an approved budget, price book, forecast or accounting record. No figure here is a legal, tax or accounting conclusion.
A4: How to read it
A5: 1. Assumptions holds every input, tagged: FACT (in the repository), POLICY (proposed default already in deal-desk.ts), HYP (hypothesis, no evidence yet), VENDOR (verify the vendor price), PRO (needs a qualified professional), ILLUS (placeholder), DECIDE (a founder / authorized-reviewer decision not yet made, mainly gate timing).
A6: 2. Scenarios holds the seven scenario columns. Each scenario has its own calculation sheet (Cons, Base, Aggr, EntDelay, HiAI, Incident, EntGated, FullScope) built from identical formulas.
A7: 3. Headcount and Schedules hold the hiring plan and the institutional pipeline schedule. Change them there, not in formulas.
A8: 4. Dashboard shows one scenario (pick 1-8 in B3). Compare shows all seven side by side. Checks must all read OK.
A9: 5. Blue cells are inputs. Black cells are formulas. Nothing is pasted from a calculation.
A11: Conventions
A12: Month 1 = January 2027. USD. Revenue is recognized as a PLANNING PROXY (ratable for subscriptions, pilots and add-ons; services over 3 months). The real policy is an accountant determination.
A13: Institutional counts are expected values, so fractions of an account appear. Collection lag on invoiced billings is fixed at 2 months. No income tax, D&A, capitalized software or financing costs are modeled.
A14: Opening capital is ILLUSTRATIVE and only drives the cash-out month. The honest funding number is "peak cumulative burn" on the Compare sheet.
A16: Regenerate: python3 docs/finance/model/build_workbook.py, then python3 docs/finance/model/verify.py (recalculates in LibreOffice and compares with the Python reference run).

Sheet Dashboard
A1: Dashboard: one scenario at a time
A3: Scenario (1-8) | B3: 2 | C3: =INDEX(Scenarios!$C$3:$J$3,B3) -> Base
A4: 1 Conservative, 2 Base, 3 Aggressive, 4 Enterprise-delayed, 5 High AI cost, 6 Incident, 7 Enterprise-delayed with gated hiring, 8 Full-scope staffing (CTO pack)
A6: Revenue and margin | B6: Year 1 (2027) | C6: Year 2 (2028) | D6: Year 3 (2029)
A7: Student subscriptions | B7: =CHOOSE($B$3,Cons!AN42,Base!AN42,Aggr!AN42,EntDelay!AN42,HiAI!AN42,Incident!AN42,EntGated!AN42,FullScope!AN42) -> 0 | C7: =CHOOSE($B$3,Cons!AO42,Base!AO42,Aggr!AO42,EntDelay!AO42,HiAI!AO42,Incident!AO42,EntGated!AO42,FullScope!AO42) -> 7305.2982 | D7: =CHOOSE($B$3,Cons!AP42,Base!AP42,Aggr!AP42,EntDelay!AP42,HiAI!AP42,Incident!AP42,EntGated!AP42,FullScope!AP42) -> 33510.939
A8: Pilot software | B8: =CHOOSE($B$3,Cons!AN129,Base!AN129,Aggr!AN129,EntDelay!AN129,HiAI!AN129,Incident!AN129,EntGated!AN129,FullScope!AN129) -> 0 | C8: =CHOOSE($B$3,Cons!AO129,Base!AO129,Aggr!AO129,EntDelay!AO129,HiAI!AO129,Incident!AO129,EntGated!AO129,FullScope!AO129) -> 150000 | D8: =CHOOSE($B$3,Cons!AP129,Base!AP129,Aggr!AP129,EntDelay!AP129,HiAI!AP129,Incident!AP129,EntGated!AP129,FullScope!AP129) -> 445000
A9: Institutional platform | B9: =CHOOSE($B$3,Cons!AN127,Base!AN127,Aggr!AN127,EntDelay!AN127,HiAI!AN127,Incident!AN127,EntGated!AN127,FullScope!AN127) -> 1320 | C9: =CHOOSE($B$3,Cons!AO127,Base!AO127,Aggr!AO127,EntDelay!AO127,HiAI!AO127,Incident!AO127,EntGated!AO127,FullScope!AO127) -> 67595.26 | D9: =CHOOSE($B$3,Cons!AP127,Base!AP127,Aggr!AP127,EntDelay!AP127,HiAI!AP127,Incident!AP127,EntGated!AP127,FullScope!AP127) -> 528450.38
A10: Implementation services | B10: =CHOOSE($B$3,Cons!AN131,Base!AN131,Aggr!AN131,EntDelay!AN131,HiAI!AN131,Incident!AN131,EntGated!AN131,FullScope!AN131) -> 0 | C10: =CHOOSE($B$3,Cons!AO131,Base!AO131,Aggr!AO131,EntDelay!AO131,HiAI!AO131,Incident!AO131,EntGated!AO131,FullScope!AO131) -> 278000 | D10: =CHOOSE($B$3,Cons!AP131,Base!AP131,Aggr!AP131,EntDelay!AP131,HiAI!AP131,Incident!AP131,EntGated!AP131,FullScope!AP131) -> 1125000
A11: AI capacity add-on | B11: =CHOOSE($B$3,Cons!AN136,Base!AN136,Aggr!AN136,EntDelay!AN136,HiAI!AN136,Incident!AN136,EntGated!AN136,FullScope!AN136) -> 0 | C11: =CHOOSE($B$3,Cons!AO136,Base!AO136,Aggr!AO136,EntDelay!AO136,HiAI!AO136,Incident!AO136,EntGated!AO136,FullScope!AO136) -> 4025.6 | D11: =CHOOSE($B$3,Cons!AP136,Base!AP136,Aggr!AP136,EntDelay!AP136,HiAI!AP136,Incident!AP136,EntGated!AP136,FullScope!AP136) -> 53345.728
A12: Alumni module | B12: =CHOOSE($B$3,Cons!AN137,Base!AN137,Aggr!AN137,EntDelay!AN137,HiAI!AN137,Incident!AN137,EntGated!AN137,FullScope!AN137) -> 0 | C12: =CHOOSE($B$3,Cons!AO137,Base!AO137,Aggr!AO137,EntDelay!AO137,HiAI!AO137,Incident!AO137,EntGated!AO137,FullScope!AO137) -> 0 | D12: =CHOOSE($B$3,Cons!AP137,Base!AP137,Aggr!AP137,EntDelay!AP137,HiAI!AP137,Incident!AP137,EntGated!AP137,FullScope!AP137) -> 6325.7
A13: Career / employer | B13: =CHOOSE($B$3,Cons!AN140,Base!AN140,Aggr!AN140,EntDelay!AN140,HiAI!AN140,Incident!AN140,EntGated!AN140,FullScope!AN140) -> 0 | C13: =CHOOSE($B$3,Cons!AO140,Base!AO140,Aggr!AO140,EntDelay!AO140,HiAI!AO140,Incident!AO140,EntGated!AO140,FullScope!AO140) -> 0 | D13: =CHOOSE($B$3,Cons!AP140,Base!AP140,Aggr!AP140,EntDelay!AP140,HiAI!AP140,Incident!AP140,EntGated!AP140,FullScope!AP140) -> 92869.806
A14: Marketplace (net take) | B14: =CHOOSE($B$3,Cons!AN144,Base!AN144,Aggr!AN144,EntDelay!AN144,HiAI!AN144,Incident!AN144,EntGated!AN144,FullScope!AN144) -> 0 | C14: =CHOOSE($B$3,Cons!AO144,Base!AO144,Aggr!AO144,EntDelay!AO144,HiAI!AO144,Incident!AO144,EntGated!AO144,FullScope!AO144) -> 0 | D14: =CHOOSE($B$3,Cons!AP144,Base!AP144,Aggr!AP144,EntDelay!AP144,HiAI!AP144,Incident!AP144,EntGated!AP144,FullScope!AP144) -> 17439.158
A15: TOTAL REVENUE | B15: =CHOOSE($B$3,Cons!AN146,Base!AN146,Aggr!AN146,EntDelay!AN146,HiAI!AN146,Incident!AN146,EntGated!AN146,FullScope!AN146) -> 1320 | C15: =CHOOSE($B$3,Cons!AO146,Base!AO146,Aggr!AO146,EntDelay!AO146,HiAI!AO146,Incident!AO146,EntGated!AO146,FullScope!AO146) -> 506926.16 | D15: =CHOOSE($B$3,Cons!AP146,Base!AP146,Aggr!AP146,EntDelay!AP146,HiAI!AP146,Incident!AP146,EntGated!AP146,FullScope!AP146) -> 2301941.7
A16: Cost of revenue | B16: =CHOOSE($B$3,Cons!AN184,Base!AN184,Aggr!AN184,EntDelay!AN184,HiAI!AN184,Incident!AN184,EntGated!AN184,FullScope!AN184) -> 208558.37 | C16: =CHOOSE($B$3,Cons!AO184,Base!AO184,Aggr!AO184,EntDelay!AO184,HiAI!AO184,Incident!AO184,EntGated!AO184,FullScope!AO184) -> 867095.12 | D16: =CHOOSE($B$3,Cons!AP184,Base!AP184,Aggr!AP184,EntDelay!AP184,HiAI!AP184,Incident!AP184,EntGated!AP184,FullScope!AP184) -> 1936630.8
A17: Gross profit | B17: =CHOOSE($B$3,Cons!AN223,Base!AN223,Aggr!AN223,EntDelay!AN223,HiAI!AN223,Incident!AN223,EntGated!AN223,FullScope!AN223) -> -207238.37 | C17: =CHOOSE($B$3,Cons!AO223,Base!AO223,Aggr!AO223,EntDelay!AO223,HiAI!AO223,Incident!AO223,EntGated!AO223,FullScope!AO223) -> -360168.96 | D17: =CHOOSE($B$3,Cons!AP223,Base!AP223,Aggr!AP223,EntDelay!AP223,HiAI!AP223,Incident!AP223,EntGated!AP223,FullScope!AP223) -> 365310.91
A19: Operating expenses | B19: Year 1 (2027) | C19: Year 2 (2028) | D19: Year 3 (2029)
A20: Engineering and product | B20: =CHOOSE($B$3,Cons!AN213,Base!AN213,Aggr!AN213,EntDelay!AN213,HiAI!AN213,Incident!AN213,EntGated!AN213,FullScope!AN213) -> 1091391.7 | C20: =CHOOSE($B$3,Cons!AO213,Base!AO213,Aggr!AO213,EntDelay!AO213,HiAI!AO213,Incident!AO213,EntGated!AO213,FullScope!AO213) -> 1931666.7 | D20: =CHOOSE($B$3,Cons!AP213,Base!AP213,Aggr!AP213,EntDelay!AP213,HiAI!AP213,Incident!AP213,EntGated!AP213,FullScope!AP213) -> 2192950
A21: Security and privacy | B21: =CHOOSE($B$3,Cons!AN214,Base!AN214,Aggr!AN214,EntDelay!AN214,HiAI!AN214,Incident!AN214,EntGated!AN214,FullScope!AN214) -> 209500 | C21: =CHOOSE($B$3,Cons!AO214,Base!AO214,Aggr!AO214,EntDelay!AO214,HiAI!AO214,Incident!AO214,EntGated!AO214,FullScope!AO214) -> 353000 | D21: =CHOOSE($B$3,Cons!AP214,Base!AP214,Aggr!AP214,EntDelay!AP214,HiAI!AP214,Incident!AP214,EntGated!AP214,FullScope!AP214) -> 418000
A22: Sales and partnerships | B22: =CHOOSE($B$3,Cons!AN215,Base!AN215,Aggr!AN215,EntDelay!AN215,HiAI!AN215,Incident!AN215,EntGated!AN215,FullScope!AN215) -> 83633.867 | C22: =CHOOSE($B$3,Cons!AO215,Base!AO215,Aggr!AO215,EntDelay!AO215,HiAI!AO215,Incident!AO215,EntGated!AO215,FullScope!AO215) -> 504057.2 | D22: =CHOOSE($B$3,Cons!AP215,Base!AP215,Aggr!AP215,EntDelay!AP215,HiAI!AP215,Incident!AP215,EntGated!AP215,FullScope!AP215) -> 980858
A23: Marketing | B23: =CHOOSE($B$3,Cons!AN216,Base!AN216,Aggr!AN216,EntDelay!AN216,HiAI!AN216,Incident!AN216,EntGated!AN216,FullScope!AN216) -> 139333.33 | C23: =CHOOSE($B$3,Cons!AO216,Base!AO216,Aggr!AO216,EntDelay!AO216,HiAI!AO216,Incident!AO216,EntGated!AO216,FullScope!AO216) -> 419608.33 | D23: =CHOOSE($B$3,Cons!AP216,Base!AP216,Aggr!AP216,EntDelay!AP216,HiAI!AP216,Incident!AP216,EntGated!AP216,FullScope!AP216) -> 601100
A24: Legal | B24: =CHOOSE($B$3,Cons!AN217,Base!AN217,Aggr!AN217,EntDelay!AN217,HiAI!AN217,Incident!AN217,EntGated!AN217,FullScope!AN217) -> 95000 | C24: =CHOOSE($B$3,Cons!AO217,Base!AO217,Aggr!AO217,EntDelay!AO217,HiAI!AO217,Incident!AO217,EntGated!AO217,FullScope!AO217) -> 112000 | D24: =CHOOSE($B$3,Cons!AP217,Base!AP217,Aggr!AP217,EntDelay!AP217,HiAI!AP217,Incident!AP217,EntGated!AP217,FullScope!AP217) -> 155000
A25: Insurance | B25: =CHOOSE($B$3,Cons!AN218,Base!AN218,Aggr!AN218,EntDelay!AN218,HiAI!AN218,Incident!AN218,EntGated!AN218,FullScope!AN218) -> 41000 | C25: =CHOOSE($B$3,Cons!AO218,Base!AO218,Aggr!AO218,EntDelay!AO218,HiAI!AO218,Incident!AO218,EntGated!AO218,FullScope!AO218) -> 70000 | D25: =CHOOSE($B$3,Cons!AP218,Base!AP218,Aggr!AP218,EntDelay!AP218,HiAI!AP218,Incident!AP218,EntGated!AP218,FullScope!AP218) -> 120000
A26: G&A | B26: =CHOOSE($B$3,Cons!AN219,Base!AN219,Aggr!AN219,EntDelay!AN219,HiAI!AN219,Incident!AN219,EntGated!AN219,FullScope!AN219) -> 587321.73 | C26: =CHOOSE($B$3,Cons!AO219,Base!AO219,Aggr!AO219,EntDelay!AO219,HiAI!AO219,Incident!AO219,EntGated!AO219,FullScope!AO219) -> 1047095.9 | D26: =CHOOSE($B$3,Cons!AP219,Base!AP219,Aggr!AP219,EntDelay!AP219,HiAI!AP219,Incident!AP219,EntGated!AP219,FullScope!AP219) -> 1342888.3
A27: Incident response | B27: =CHOOSE($B$3,Cons!AN220,Base!AN220,Aggr!AN220,EntDelay!AN220,HiAI!AN220,Incident!AN220,EntGated!AN220,FullScope!AN220) -> 0 | C27: =CHOOSE($B$3,Cons!AO220,Base!AO220,Aggr!AO220,EntDelay!AO220,HiAI!AO220,Incident!AO220,EntGated!AO220,FullScope!AO220) -> 0 | D27: =CHOOSE($B$3,Cons!AP220,Base!AP220,Aggr!AP220,EntDelay!AP220,HiAI!AP220,Incident!AP220,EntGated!AP220,FullScope!AP220) -> 0
A28: TOTAL OPERATING EXPENSES | B28: =CHOOSE($B$3,Cons!AN221,Base!AN221,Aggr!AN221,EntDelay!AN221,HiAI!AN221,Incident!AN221,EntGated!AN221,FullScope!AN221) -> 2247180.6 | C28: =CHOOSE($B$3,Cons!AO221,Base!AO221,Aggr!AO221,EntDelay!AO221,HiAI!AO221,Incident!AO221,EntGated!AO221,FullScope!AO221) -> 4437428.1 | D28: =CHOOSE($B$3,Cons!AP221,Base!AP221,Aggr!AP221,EntDelay!AP221,HiAI!AP221,Incident!AP221,EntGated!AP221,FullScope!AP221) -> 5810796.3
A29: Operating result (EBITDA) | B29: =CHOOSE($B$3,Cons!AN225,Base!AN225,Aggr!AN225,EntDelay!AN225,HiAI!AN225,Incident!AN225,EntGated!AN225,FullScope!AN225) -> -2454419 | C29: =CHOOSE($B$3,Cons!AO225,Base!AO225,Aggr!AO225,EntDelay!AO225,HiAI!AO225,Incident!AO225,EntGated!AO225,FullScope!AO225) -> -4797597.1 | D29: =CHOOSE($B$3,Cons!AP225,Base!AP225,Aggr!AP225,EntDelay!AP225,HiAI!AP225,Incident!AP225,EntGated!AP225,FullScope!AP225) -> -5445485.4
A31: Cash | B31: Year 1 (2027) | C31: Year 2 (2028) | D31: Year 3 (2029)
A32: Cash collected | B32: =CHOOSE($B$3,Cons!AN153,Base!AN153,Aggr!AN153,EntDelay!AN153,HiAI!AN153,Incident!AN153,EntGated!AN153,FullScope!AN153) -> 0 | C32: =CHOOSE($B$3,Cons!AO153,Base!AO153,Aggr!AO153,EntDelay!AO153,HiAI!AO153,Incident!AO153,EntGated!AO153,FullScope!AO153) -> 524233.94 | D32: =CHOOSE($B$3,Cons!AP153,Base!AP153,Aggr!AP153,EntDelay!AP153,HiAI!AP153,Incident!AP153,EntGated!AP153,FullScope!AP153) -> 2256267.3
A33: Operating cash flow | B33: =CHOOSE($B$3,Cons!AN226,Base!AN226,Aggr!AN226,EntDelay!AN226,HiAI!AN226,Incident!AN226,EntGated!AN226,FullScope!AN226) -> -2455739 | C33: =CHOOSE($B$3,Cons!AO226,Base!AO226,Aggr!AO226,EntDelay!AO226,HiAI!AO226,Incident!AO226,EntGated!AO226,FullScope!AO226) -> -4780289.3 | D33: =CHOOSE($B$3,Cons!AP226,Base!AP226,Aggr!AP226,EntDelay!AP226,HiAI!AP226,Incident!AP226,EntGated!AP226,FullScope!AP226) -> -5491159.8
A34: Cumulative operating cash flow | B34: =CHOOSE($B$3,Cons!AN227,Base!AN227,Aggr!AN227,EntDelay!AN227,HiAI!AN227,Incident!AN227,EntGated!AN227,FullScope!AN227) -> -2455739 | C34: =CHOOSE($B$3,Cons!AO227,Base!AO227,Aggr!AO227,EntDelay!AO227,HiAI!AO227,Incident!AO227,EntGated!AO227,FullScope!AO227) -> -7236028.2 | D34: =CHOOSE($B$3,Cons!AP227,Base!AP227,Aggr!AP227,EntDelay!AP227,HiAI!AP227,Incident!AP227,EntGated!AP227,FullScope!AP227) -> -12727188
A35: Illustrative cash balance | B35: =CHOOSE($B$3,Cons!AN228,Base!AN228,Aggr!AN228,EntDelay!AN228,HiAI!AN228,Incident!AN228,EntGated!AN228,FullScope!AN228) -> 544261.03 | C35: =CHOOSE($B$3,Cons!AO228,Base!AO228,Aggr!AO228,EntDelay!AO228,HiAI!AO228,Incident!AO228,EntGated!AO228,FullScope!AO228) -> -4236028.2 | D35: =CHOOSE($B$3,Cons!AP228,Base!AP228,Aggr!AP228,EntDelay!AP228,HiAI!AP228,Incident!AP228,EntGated!AP228,FullScope!AP228) -> -9727188
A36: Deferred revenue | B36: =CHOOSE($B$3,Cons!AN154,Base!AN154,Aggr!AN154,EntDelay!AN154,HiAI!AN154,Incident!AN154,EntGated!AN154,FullScope!AN154) -> 14520 | C36: =CHOOSE($B$3,Cons!AO154,Base!AO154,Aggr!AO154,EntDelay!AO154,HiAI!AO154,Incident!AO154,EntGated!AO154,FullScope!AO154) -> 120222.61 | D36: =CHOOSE($B$3,Cons!AP154,Base!AP154,Aggr!AP154,EntDelay!AP154,HiAI!AP154,Incident!AP154,EntGated!AP154,FullScope!AP154) -> 1013459.2
A37: Receivables | B37: =CHOOSE($B$3,Cons!AN155,Base!AN155,Aggr!AN155,EntDelay!AN155,HiAI!AN155,Incident!AN155,EntGated!AN155,FullScope!AN155) -> 15681.6 | C37: =CHOOSE($B$3,Cons!AO155,Base!AO155,Aggr!AO155,EntDelay!AO155,HiAI!AO155,Incident!AO155,EntGated!AO155,FullScope!AO155) -> 98102.189 | D37: =CHOOSE($B$3,Cons!AP155,Base!AP155,Aggr!AP155,EntDelay!AP155,HiAI!AP155,Incident!AP155,EntGated!AP155,FullScope!AP155) -> 1007154.9
A39: Scale | B39: Year 1 (2027) | C39: Year 2 (2028) | D39: Year 3 (2029)
A40: ARR | B40: =CHOOSE($B$3,Cons!AN148,Base!AN148,Aggr!AN148,EntDelay!AN148,HiAI!AN148,Incident!AN148,EntGated!AN148,FullScope!AN148) -> 15840 | C40: =CHOOSE($B$3,Cons!AO148,Base!AO148,Aggr!AO148,EntDelay!AO148,HiAI!AO148,Incident!AO148,EntGated!AO148,FullScope!AO148) -> 163394.4 | D40: =CHOOSE($B$3,Cons!AP148,Base!AP148,Aggr!AP148,EntDelay!AP148,HiAI!AP148,Incident!AP148,EntGated!AP148,FullScope!AP148) -> 1527680.4
A41: ARR, institutional | B41: =CHOOSE($B$3,Cons!AN149,Base!AN149,Aggr!AN149,EntDelay!AN149,HiAI!AN149,Incident!AN149,EntGated!AN149,FullScope!AN149) -> 15840 | C41: =CHOOSE($B$3,Cons!AO149,Base!AO149,Aggr!AO149,EntDelay!AO149,HiAI!AO149,Incident!AO149,EntGated!AO149,FullScope!AO149) -> 146050.32 | D41: =CHOOSE($B$3,Cons!AP149,Base!AP149,Aggr!AP149,EntDelay!AP149,HiAI!AP149,Incident!AP149,EntGated!AP149,FullScope!AP149) -> 1479349.3
A42: ARR, student | B42: =CHOOSE($B$3,Cons!AN150,Base!AN150,Aggr!AN150,EntDelay!AN150,HiAI!AN150,Incident!AN150,EntGated!AN150,FullScope!AN150) -> 0 | C42: =CHOOSE($B$3,Cons!AO150,Base!AO150,Aggr!AO150,EntDelay!AO150,HiAI!AO150,Incident!AO150,EntGated!AO150,FullScope!AO150) -> 17344.081 | D42: =CHOOSE($B$3,Cons!AP150,Base!AP150,Aggr!AP150,EntDelay!AP150,HiAI!AP150,Incident!AP150,EntGated!AP150,FullScope!AP150) -> 48331.129
A43: Annual logos | B43: =CHOOSE($B$3,Cons!AN122,Base!AN122,Aggr!AN122,EntDelay!AN122,HiAI!AN122,Incident!AN122,EntGated!AN122,FullScope!AN122) -> 0.6 | C43: =CHOOSE($B$3,Cons!AO122,Base!AO122,Aggr!AO122,EntDelay!AO122,HiAI!AO122,Incident!AO122,EntGated!AO122,FullScope!AO122) -> 3.578 | D43: =CHOOSE($B$3,Cons!AP122,Base!AP122,Aggr!AP122,EntDelay!AP122,HiAI!AP122,Incident!AP122,EntGated!AP122,FullScope!AP122) -> 24.39864
A44: Pilots running | B44: =CHOOSE($B$3,Cons!AN123,Base!AN123,Aggr!AN123,EntDelay!AN123,HiAI!AN123,Incident!AN123,EntGated!AN123,FullScope!AN123) -> 1 | C44: =CHOOSE($B$3,Cons!AO123,Base!AO123,Aggr!AO123,EntDelay!AO123,HiAI!AO123,Incident!AO123,EntGated!AO123,FullScope!AO123) -> 6 | D44: =CHOOSE($B$3,Cons!AP123,Base!AP123,Aggr!AP123,EntDelay!AP123,HiAI!AP123,Incident!AP123,EntGated!AP123,FullScope!AP123) -> 12
A45: Paying students | B45: =CHOOSE($B$3,Cons!AN39,Base!AN39,Aggr!AN39,EntDelay!AN39,HiAI!AN39,Incident!AN39,EntGated!AN39,FullScope!AN39) -> 0 | C45: =CHOOSE($B$3,Cons!AO39,Base!AO39,Aggr!AO39,EntDelay!AO39,HiAI!AO39,Incident!AO39,EntGated!AO39,FullScope!AO39) -> 256.9664 | D45: =CHOOSE($B$3,Cons!AP39,Base!AP39,Aggr!AP39,EntDelay!AP39,HiAI!AP39,Incident!AP39,EntGated!AP39,FullScope!AP39) -> 719.9672
...

Sheet Compare
A1: Scenario comparison (live: every cell reads the scenario sheets)
A3: Metric | B3: Conservative | C3: Base | D3: Aggressive | E3: Enterprise-delayed | F3: High AI cost | G3: Incident (SEV-0, month 14) | H3: Enterprise-delayed, gated hiring (mitigation) | I3: Full-scope staffing (CTO pack S1-S4), Base revenue
A4: Revenue, Year 1 | B4: =Cons!AN146 -> 0 | C4: =Base!AN146 -> 1320 | D4: =Aggr!AN146 -> 28052 | E4: =EntDelay!AN146 -> 0 | F4: =HiAI!AN146 -> 1320 | G4: =Incident!AN146 -> 1320 | H4: =EntGated!AN146 -> 0 | I4: =FullScope!AN146 -> 1320
A5: Revenue, Year 2 | B5: =Cons!AO146 -> 227178.67 | C5: =Base!AO146 -> 506926.16 | D5: =Aggr!AO146 -> 915384.65 | E5: =EntDelay!AO146 -> 166843.3 | F5: =HiAI!AO146 -> 506926.16 | G5: =Incident!AO146 -> 343437.13 | H5: =EntGated!AO146 -> 166843.3 | I5: =FullScope!AO146 -> 506926.16
A6: Revenue, Year 3 | B6: =Cons!AP146 -> 1059403.9 | C6: =Base!AP146 -> 2301941.7 | D6: =Aggr!AP146 -> 3998129.9 | E6: =EntDelay!AP146 -> 1255579.2 | F6: =HiAI!AP146 -> 2301941.7 | G6: =Incident!AP146 -> 2244826.9 | H6: =EntGated!AP146 -> 1255579.2 | I6: =FullScope!AP146 -> 2301941.7
A7: ARR, month 12 | B7: =Cons!AN148 -> 0 | C7: =Base!AN148 -> 15840 | D7: =Aggr!AN148 -> 17424 | E7: =EntDelay!AN148 -> 0 | F7: =HiAI!AN148 -> 15840 | G7: =Incident!AN148 -> 15840 | H7: =EntGated!AN148 -> 0 | I7: =FullScope!AN148 -> 15840
A8: ARR, month 24 | B8: =Cons!AO148 -> 64050.328 | C8: =Base!AO148 -> 163394.4 | D8: =Aggr!AO148 -> 456730.18 | E8: =EntDelay!AO148 -> 77176.081 | F8: =HiAI!AO148 -> 163394.4 | G8: =Incident!AO148 -> 135929.75 | H8: =EntGated!AO148 -> 77176.081 | I8: =FullScope!AO148 -> 163394.4
A9: ARR, month 36 | B9: =Cons!AP148 -> 531664.39 | C9: =Base!AP148 -> 1527680.4 | D9: =Aggr!AP148 -> 2818093.1 | E9: =EntDelay!AP148 -> 728214.21 | F9: =HiAI!AP148 -> 1527680.4 | G9: =Incident!AP148 -> 1463532.3 | H9: =EntGated!AP148 -> 728214.21 | I9: =FullScope!AP148 -> 1527680.4
A10: Annual logos, month 36 | B10: =Cons!AP122 -> 9.204 | C10: =Base!AP122 -> 24.39864 | D10: =Aggr!AP122 -> 45.950975 | E10: =EntDelay!AP122 -> 10.8654 | F10: =HiAI!AP122 -> 24.39864 | G10: =Incident!AP122 -> 22.94784 | H10: =EntGated!AP122 -> 10.8654 | I10: =FullScope!AP122 -> 24.39864
A11: Paying students, month 36 | B11: =Cons!AP39 -> 354.29378 | C11: =Base!AP39 -> 719.9672 | D11: =Aggr!AP39 -> 1266.8546 | E11: =EntDelay!AP39 -> 719.9672 | F11: =HiAI!AP39 -> 719.9672 | G11: =Incident!AP39 -> 718.96313 | H11: =EntGated!AP39 -> 719.9672 | I11: =FullScope!AP39 -> 719.9672
A12: Gross margin, Year 3 | B12: =Cons!AP237 -> -0.6899905 | C12: =Base!AP237 -> 0.15869686 | D12: =Aggr!AP237 -> 0.46284003 | E12: =EntDelay!AP237 -> -0.45185041 | F12: =HiAI!AP237 -> 0.012996709 | G12: =Incident!AP237 -> 0.14402104 | H12: =EntGated!AP237 -> -0.20488604 | I12: =FullScope!AP237 -> 0.15869686
A13: Contribution margin, Year 3 | B13: =Cons!AP238 -> -0.83333492 | C13: =Base!AP238 -> 0.03132265 | D13: =Aggr!AP238 -> 0.35232348 | E13: =EntDelay!AP238 -> -0.59516989 | F13: =HiAI!AP238 -> -0.1143775 | G13: =Incident!AP238 -> 0.014690296 | H13: =EntGated!AP238 -> -0.34820552 | I13: =FullScope!AP238 -> 0.03132265
A14: Operating result, Year 1 | B14: =Cons!AN225 -> -2452578.1 | C14: =Base!AN225 -> -2454419 | D14: =Aggr!AN225 -> -2435255.3 | E14: =EntDelay!AN225 -> -2453970.7 | F14: =HiAI!AN225 -> -2463990 | G14: =Incident!AN225 -> -2454419 | H14: =EntGated!AN225 -> -2318170.7 | I14: =FullScope!AN225 -> -3138185.6
A15: Operating result, Year 2 | B15: =Cons!AO225 -> -5018193 | C15: =Base!AO225 -> -4797597.1 | D15: =Aggr!AO225 -> -4505533.6 | E15: =EntDelay!AO225 -> -5076094.5 | F15: =HiAI!AO225 -> -4886552.6 | G15: =Incident!AO225 -> -5634046.3 | H15: =EntGated!AO225 -> -4620244.5 | I15: =FullScope!AO225 -> -8109980.4
A16: Operating result, Year 3 | B16: =Cons!AP225 -> -6382264.8 | C16: =Base!AP225 -> -5445485.4 | D16: =Aggr!AP225 -> -4129633.2 | E16: =EntDelay!AP225 -> -6250150.8 | F16: =HiAI!AP225 -> -5780878.6 | G16: =Incident!AP225 -> -5484038.8 | H16: =EntGated!AP225 -> -5816367.5 | I16: =FullScope!AP225 -> -10842352
A17: Net burn, Year 1 | B17: =Cons!AN245 -> 2452578.1 | C17: =Base!AN245 -> 2455739 | D17: =Aggr!AN245 -> 2463307.3 | E17: =EntDelay!AN245 -> 2453970.7 | F17: =HiAI!AN245 -> 2465310 | G17: =Incident!AN245 -> 2455739 | H17: =EntGated!AN245 -> 2318170.7 | I17: =FullScope!AN245 -> 3139505.6
A18: Net burn, Year 2 | B18: =Cons!AO245 -> 5019727.7 | C18: =Base!AO245 -> 4780289.3 | D18: =Aggr!AO245 -> 4575996.8 | E18: =EntDelay!AO245 -> 5028976.3 | F18: =HiAI!AO245 -> 4869244.8 | G18: =Incident!AO245 -> 5611294.4 | H18: =EntGated!AO245 -> 4573126.3 | I18: =FullScope!AO245 -> 8092672.6
A19: Net burn, Year 3 | B19: =Cons!AP245 -> 6258663.4 | C19: =Base!AP245 -> 5491159.8 | D19: =Aggr!AP245 -> 3620884.8 | E19: =EntDelay!AP245 -> 6254569.5 | F19: =HiAI!AP245 -> 5826553 | G19: =Incident!AP245 -> 5530591.5 | H19: =EntGated!AP245 -> 5820786.2 | I19: =FullScope!AP245 -> 10888026
A20: Cumulative cash need through month 12 | B20: =-Cons!AN227 -> 2452578.1 | C20: =-Base!AN227 -> 2455739 | D20: =-Aggr!AN227 -> 2463307.3 | E20: =-EntDelay!AN227 -> 2453970.7 | F20: =-HiAI!AN227 -> 2465310 | G20: =-Incident!AN227 -> 2455739 | H20: =-EntGated!AN227 -> 2318170.7 | I20: =-FullScope!AN227 -> 3139505.6
A21: Cumulative cash need through month 24 | B21: =-Cons!AO227 -> 7472305.8 | C21: =-Base!AO227 -> 7236028.2 | D21: =-Aggr!AO227 -> 7039304.1 | E21: =-EntDelay!AO227 -> 7482947 | F21: =-HiAI!AO227 -> 7334554.8 | G21: =-Incident!AO227 -> 8067033.3 | H21: =-EntGated!AO227 -> 6891297 | I21: =-FullScope!AO227 -> 11232178
A22: Cumulative cash need through month 36 | B22: =-Cons!AP227 -> 13730969 | C22: =-Base!AP227 -> 12727188 | D22: =-Aggr!AP227 -> 10660189 | E22: =-EntDelay!AP227 -> 13737516 | F22: =-HiAI!AP227 -> 13161108 | G22: =-Incident!AP227 -> 13597625 | H22: =-EntGated!AP227 -> 12712083 | I22: =-FullScope!AP227 -> 22120205
A23: PEAK FUNDING NEED (deepest cumulative cash trough, months 1-36) | B23: =-MIN(Cons!C227:AL227) -> 13730969 | C23: =-MIN(Base!C227:AL227) -> 12727188 | D23: =-MIN(Aggr!C227:AL227) -> 10694710 | E23: =-MIN(EntDelay!C227:AL227) -> 13737516 | F23: =-MIN(HiAI!C227:AL227) -> 13161108 | G23: =-MIN(Incident!C227:AL227) -> 13597625 | H23: =-MIN(EntGated!C227:AL227) -> 12712083 | I23: =-MIN(FullScope!C227:AL227) -> 22120205
A24: Month cash runs out on the illustrative opening capital (blank = not within 36 months) | B24: =IFERROR(MATCH(1,Cons!C229:AL229,0),"") -> 14 | C24: =IFERROR(MATCH(1,Base!C229:AL229,0),"") -> 14 | D24: =IFERROR(MATCH(1,Aggr!C229:AL229,0),"") -> 14 | E24: =IFERROR(MATCH(1,EntDelay!C229:AL229,0),"") -> 14 | F24: =IFERROR(MATCH(1,HiAI!C229:AL229,0),"") -> 14 | G24: =IFERROR(MATCH(1,Incident!C229:AL229,0),"") -> 14 | H24: =IFERROR(MATCH(1,EntGated!C229:AL229,0),"") -> 15 | I24: =IFERROR(MATCH(1,FullScope!C229:AL229,0),"") -> 12
A25: Burn multiple, Year 3 | B25: =Cons!AP249 -> 13.38425 | C25: =Base!AP249 -> 4.0249331 | D25: =Aggr!AP249 -> 1.5333876 | E25: =EntDelay!AP249 -> 9.6070709 | F25: =HiAI!AP249 -> 4.270771 | G25: =Incident!AP249 -> 4.1658489 | H25: =EntGated!AP249 -> 8.9407761 | I25: =FullScope!AP249 -> 7.9807508
A26: Implementation margin, Year 3 (actual team cost) | B26: =Cons!AP241 -> -0.69558133 | C26: =Base!AP241 -> 0.21377778 | D26: =Aggr!AP241 -> 0.54383703 | E26: =EntDelay!AP241 -> -0.42202572 | F26: =HiAI!AP241 -> 0.21377778 | G26: =Incident!AP241 -> 0.21377778 | H26: =EntGated!AP241 -> -0.078778135 | I26: =FullScope!AP241 -> 0.21377778
A27: Implementation utilization, Year 3 | B27: =Cons!AP243 -> 0.47680251 | C27: =Base!AP243 -> 1.0824451 | D27: =Aggr!AP243 -> 1.694629 | E27: =EntDelay!AP243 -> 0.59435737 | F27: =HiAI!AP243 -> 1.0824451 | G27: =Incident!AP243 -> 1.0824451 | H27: =EntGated!AP243 -> 0.78347107 | I27: =FullScope!AP243 -> 1.0824451
A28: Student LTV / CAC, Year 3 | B28: =Cons!AP268 -> 0.090155814 | C28: =Base!AP268 -> 0.20017006 | D28: =Aggr!AP268 -> 0.36857617 | E28: =EntDelay!AP268 -> 0.20017006 | F28: =HiAI!AP268 -> 0.092456588 | G28: =Incident!AP268 -> 0.2003196 | H28: =EntGated!AP268 -> 0.20017006 | I28: =FullScope!AP268 -> 0.20017006
A29: AI cost as share of revenue, Year 3 | B29: =Cons!AP263 -> 0.11501075 | C29: =Base!AP263 -> 0.079046824 | D29: =Aggr!AP263 -> 0.068024311 | E29: =EntDelay!AP263 -> 0.10726571 | F29: =HiAI!AP263 -> 0.22474697 | G29: =Incident!AP263 -> 0.078215714 | H29: =EntGated!AP263 -> 0.10726571 | I29: =FullScope!AP263 -> 0.079046824
A30: Headcount, month 36 (FTE) | B30: =Cons!AP196 -> 40.4 | C30: =Base!AP196 -> 40.4 | D30: =Aggr!AP196 -> 40.4 | E30: =EntDelay!AP196 -> 40.4 | F30: =HiAI!AP196 -> 40.4 | G30: =Incident!AP196 -> 40.4 | H30: =EntGated!AP196 -> 38.4 | I30: =FullScope!AP196 -> 70.4

Sheet Checks
A1: Model integrity checks (every line must read OK)
A3: Check | B3: Cons | C3: Base | D3: Aggr | E3: EntDelay | F3: HiAI | G3: Incident | H3: EntGated | I3: FullScope
A4: Cost-of-revenue lines sum to the allocated total (max abs difference < $0.01) | B4: =IF(AND(MAX(Cons!C185:AL185)<0.01,MIN(Cons!C185:AL185)>-0.01),"OK","FAIL") -> OK | C4: =IF(AND(MAX(Base!C185:AL185)<0.01,MIN(Base!C185:AL185)>-0.01),"OK","FAIL") -> OK | D4: =IF(AND(MAX(Aggr!C185:AL185)<0.01,MIN(Aggr!C185:AL185)>-0.01),"OK","FAIL") -> OK | E4: =IF(AND(MAX(EntDelay!C185:AL185)<0.01,MIN(EntDelay!C185:AL185)>-0.01),"OK","FAIL") -> OK | F4: =IF(AND(MAX(HiAI!C185:AL185)<0.01,MIN(HiAI!C185:AL185)>-0.01),"OK","FAIL") -> OK | G4: =IF(AND(MAX(Incident!C185:AL185)<0.01,MIN(Incident!C185:AL185)>-0.01),"OK","FAIL") -> OK | H4: =IF(AND(MAX(EntGated!C185:AL185)<0.01,MIN(EntGated!C185:AL185)>-0.01),"OK","FAIL") -> OK | I4: =IF(AND(MAX(FullScope!C185:AL185)<0.01,MIN(FullScope!C185:AL185)>-0.01),"OK","FAIL") -> OK
A5: Deferred revenue never negative | B5: =IF(MIN(Cons!C154:AL154)>-0.01,"OK","FAIL") -> OK | C5: =IF(MIN(Base!C154:AL154)>-0.01,"OK","FAIL") -> OK | D5: =IF(MIN(Aggr!C154:AL154)>-0.01,"OK","FAIL") -> OK | E5: =IF(MIN(EntDelay!C154:AL154)>-0.01,"OK","FAIL") -> OK | F5: =IF(MIN(HiAI!C154:AL154)>-0.01,"OK","FAIL") -> OK | G5: =IF(MIN(Incident!C154:AL154)>-0.01,"OK","FAIL") -> OK | H5: =IF(MIN(EntGated!C154:AL154)>-0.01,"OK","FAIL") -> OK | I5: =IF(MIN(FullScope!C154:AL154)>-0.01,"OK","FAIL") -> OK
A6: Receivables never negative | B6: =IF(MIN(Cons!C155:AL155)>-0.01,"OK","FAIL") -> OK | C6: =IF(MIN(Base!C155:AL155)>-0.01,"OK","FAIL") -> OK | D6: =IF(MIN(Aggr!C155:AL155)>-0.01,"OK","FAIL") -> OK | E6: =IF(MIN(EntDelay!C155:AL155)>-0.01,"OK","FAIL") -> OK | F6: =IF(MIN(HiAI!C155:AL155)>-0.01,"OK","FAIL") -> OK | G6: =IF(MIN(Incident!C155:AL155)>-0.01,"OK","FAIL") -> OK | H6: =IF(MIN(EntGated!C155:AL155)>-0.01,"OK","FAIL") -> OK | I6: =IF(MIN(FullScope!C155:AL155)>-0.01,"OK","FAIL") -> OK
A7: Cumulative cash equals the sum of monthly operating cash flow | B7: =IF(ABS(SUM(Cons!C226:AL226)-Cons!AL227)<0.01,"OK","FAIL") -> OK | C7: =IF(ABS(SUM(Base!C226:AL226)-Base!AL227)<0.01,"OK","FAIL") -> OK | D7: =IF(ABS(SUM(Aggr!C226:AL226)-Aggr!AL227)<0.01,"OK","FAIL") -> OK | E7: =IF(ABS(SUM(EntDelay!C226:AL226)-EntDelay!AL227)<0.01,"OK","FAIL") -> OK | F7: =IF(ABS(SUM(HiAI!C226:AL226)-HiAI!AL227)<0.01,"OK","FAIL") -> OK | G7: =IF(ABS(SUM(Incident!C226:AL226)-Incident!AL227)<0.01,"OK","FAIL") -> OK | H7: =IF(ABS(SUM(EntGated!C226:AL226)-EntGated!AL227)<0.01,"OK","FAIL") -> OK | I7: =IF(ABS(SUM(FullScope!C226:AL226)-FullScope!AL227)<0.01,"OK","FAIL") -> OK
A8: Billings less revenue equals deferred revenue at month 36 | B8: =IF(ABS(SUM(Cons!C151:AL151)-SUM(Cons!C146:AL146)-Cons!AL154)<0.01,"OK","FAIL") -> OK | C8: =IF(ABS(SUM(Base!C151:AL151)-SUM(Base!C146:AL146)-Base!AL154)<0.01,"OK","FAIL") -> OK | D8: =IF(ABS(SUM(Aggr!C151:AL151)-SUM(Aggr!C146:AL146)-Aggr!AL154)<0.01,"OK","FAIL") -> OK | E8: =IF(ABS(SUM(EntDelay!C151:AL151)-SUM(EntDelay!C146:AL146)-EntDelay!AL154)<0.01,"OK","FAIL") -> OK | F8: =IF(ABS(SUM(HiAI!C151:AL151)-SUM(HiAI!C146:AL146)-HiAI!AL154)<0.01,"OK","FAIL") -> OK | G8: =IF(ABS(SUM(Incident!C151:AL151)-SUM(Incident!C146:AL146)-Incident!AL154)<0.01,"OK","FAIL") -> OK | H8: =IF(ABS(SUM(EntGated!C151:AL151)-SUM(EntGated!C146:AL146)-EntGated!AL154)<0.01,"OK","FAIL") -> OK | I8: =IF(ABS(SUM(FullScope!C151:AL151)-SUM(FullScope!C146:AL146)-FullScope!AL154)<0.01,"OK","FAIL") -> OK
A9: Headcount at month 36 equals month-1 headcount plus hires from month 2 | B9: =IF(ABS(Cons!C196+SUM(Cons!D198:AL198)-Cons!AL196)<0.001,"OK","FAIL") -> OK | C9: =IF(ABS(Base!C196+SUM(Base!D198:AL198)-Base!AL196)<0.001,"OK","FAIL") -> OK | D9: =IF(ABS(Aggr!C196+SUM(Aggr!D198:AL198)-Aggr!AL196)<0.001,"OK","FAIL") -> OK | E9: =IF(ABS(EntDelay!C196+SUM(EntDelay!D198:AL198)-EntDelay!AL196)<0.001,"OK","FAIL") -> OK | F9: =IF(ABS(HiAI!C196+SUM(HiAI!D198:AL198)-HiAI!AL196)<0.001,"OK","FAIL") -> OK | G9: =IF(ABS(Incident!C196+SUM(Incident!D198:AL198)-Incident!AL196)<0.001,"OK","FAIL") -> OK | H9: =IF(ABS(EntGated!C196+SUM(EntGated!D198:AL198)-EntGated!AL196)<0.001,"OK","FAIL") -> OK | I9: =IF(ABS(FullScope!C196+SUM(FullScope!D198:AL198)-FullScope!AL196)<0.001,"OK","FAIL") -> OK
A10: No subscriber, user or logo count below zero | B10: =IF(MIN(Cons!C29:AL29,Cons!C39:AL39,Cons!C122:AL122)>-0.001,"OK","FAIL") -> OK | C10: =IF(MIN(Base!C29:AL29,Base!C39:AL39,Base!C122:AL122)>-0.001,"OK","FAIL") -> OK | D10: =IF(MIN(Aggr!C29:AL29,Aggr!C39:AL39,Aggr!C122:AL122)>-0.001,"OK","FAIL") -> OK | E10: =IF(MIN(EntDelay!C29:AL29,EntDelay!C39:AL39,EntDelay!C122:AL122)>-0.001,"OK","FAIL") -> OK | F10: =IF(MIN(HiAI!C29:AL29,HiAI!C39:AL39,HiAI!C122:AL122)>-0.001,"OK","FAIL") -> OK | G10: =IF(MIN(Incident!C29:AL29,Incident!C39:AL39,Incident!C122:AL122)>-0.001,"OK","FAIL") -> OK | H10: =IF(MIN(EntGated!C29:AL29,EntGated!C39:AL39,EntGated!C122:AL122)>-0.001,"OK","FAIL") -> OK | I10: =IF(MIN(FullScope!C29:AL29,FullScope!C39:AL39,FullScope!C122:AL122)>-0.001,"OK","FAIL") -> OK
A11: Seasonality index sums to 12 | B11: =IF(ABS(Assumptions!$C$179-12)<0.0001,"OK","FAIL") -> OK
A12: ALL CHECKS | B12: =IF(COUNTIF(B4:I11,"FAIL")=0,"OK","FAIL") -> OK

Sheet Scenarios
A1: Scenario parameters
A3: Parameter | B3: Unit | C3: Conservative | D3: Base | E3: Aggressive | F3: Enterprise-delayed | G3: High AI cost | H3: Incident (SEV-0, month 14) | I3: Enterprise-delayed, gated hiring (mitigation) | J3: Full-scope staffing (CTO pack S1-S4), Base revenue | K3: Note
A4: Organic student acquisition multiplier | B4: x | C4: 0.6 | D4: 1 | E4: 1.5 | F4: 1 | G4: 1 | H4: 1 | I4: 1 | J4: 1
A5: Free-to-paid conversion multiplier | B5: x | C5: 0.8 | D5: 1 | E5: 1.2 | F5: 1 | G5: 1 | H5: 1 | I5: 1 | J5: 1
A6: Churn multiplier (students and institutions) | B6: x | C6: 1.25 | D6: 1 | E6: 0.85 | F6: 1 | G6: 1 | H6: 1 | I6: 1 | J6: 1
A7: Pilot and direct-deal volume multiplier | B7: x | C7: 0.6 | D7: 1 | E7: 1.4 | F7: 1 | G7: 1 | H7: 1 | I7: 1 | J7: 1
A8: Pilot-to-annual conversion multiplier | B8: x | C8: 0.8 | D8: 1 | E8: 1.1 | F8: 0.9 | G8: 1 | H8: 1 | I8: 0.9 | J8: 1
A9: Institutional gates slip by (months) | B9: months | C9: 2 | D9: 0 | E9: -2 | F9: 6 | G9: 0 | H9: 0 | I9: 6 | J9: 0 | K9: Slips (negative = earlier) the paid-pilot, direct and enterprise gates (and design-partner conversion).
A10: Institutional price realization multiplier | B10: x | C10: 0.95 | D10: 1 | E10: 1 | F10: 1 | G10: 1 | H10: 1 | I10: 1 | J10: 1
A11: Paid acquisition cost multiplier | B11: x | C11: 1.25 | D11: 1 | E11: 0.85 | F11: 1 | G11: 1 | H11: 1 | I11: 1 | J11: 1
A12: AI unit cost multiplier (price or model-mix shift) | B12: x | C12: 1 | D12: 1 | E12: 1 | F12: 1 | G12: 2.5 | H12: 1 | I12: 1 | J12: 1
A13: AI usage multiplier (requests per user) | B13: x | C13: 1 | D13: 1 | E13: 1 | F13: 1 | G13: 1.5 | H13: 1 | I13: 1 | J13: 1
A14: Incident switch (1 = on) | B14: 0/1 | C14: 0 | D14: 0 | E14: 0 | F14: 0 | G14: 0 | H14: 1 | I14: 0 | J14: 0
A15: Delay for gated hires (months) | B15: months | C15: 0 | D15: 0 | E15: 0 | F15: 0 | G15: 0 | H15: 0 | I15: 6 | J15: 0 | K15: Mitigation lever: sales, implementation, CS, partnerships roles wait for the evidence gate.
A16: Full-scope staffing switch (1 = include the CTO-pack staffing roles) | B16: 0/1 | C16: 0 | D16: 0 | E16: 0 | F16: 0 | G16: 0 | H16: 0 | I16: 0 | J16: 1 | K16: Same revenue as Base; costs the staffing plan proposed in docs/target-architecture/08.
A19: Incident cost inputs live on Assumptions (group: Incident scenario). They apply only where the incident switch is 1.

Sheet Assumptions
A1: Assumptions register (every number is a planning assumption unless tagged FACT)
A3: ID | B3: Assumption | C3: Value | D3: Unit | E3: Tag | F3: Source / what would change it
A4: Go / no-go gates (controlling document: GO-NO-GO-DECISION.md, 3 Oct 2026)
A5: gate_plus | B5: Month broad / paid individual acquisition may begin (checkout hold lifted) | C5: 13 | D5: month | E5: DECIDE | F5: Today NO-GO (INDIVIDUAL_PAID_ACQUISITION_ENABLED = false). Needs invitation-validation closeout + a separate broad-rollout decision.
A6: pre_gate_share | B6: Share of organic signups before that gate (invitation-only, unpaid validation cohorts) | C6: 0.25 | D6: % | E6: DECIDE | F6: Conditional GO covers invitation-only, unpaid validation only.
A7: gate_pilot | B7: Month the first PAID institutional pilot may begin | C7: 12 | D7: month | E7: DECIDE | F7: Today NO-GO. Reconsidered only after a design-partner pilot has an approved activation record and a measured 26-week closeout (D-134).
A8: gate_direct | B8: Month direct annual sales (no pilot first) may begin | C8: 22 | D8: month | E8: DECIDE | F8: After the first pilot-to-annual conversions are evidenced.
A9: gate_ent | B9: Month System-tier / broad enterprise sale may begin | C9: 26 | D9: month | E9: DECIDE | F9: Last motion to reconsider: repeated deployments and independent assurance first.
A10: dp_rho | B10: Design-partner pilot to paid annual conversion | C10: 0.6 | D10: % | E10: HYP | F10: Unpaid design partners; converts only after the paid-pilot gate.
A11: Student subscription
A12: price_m | B12: Plus list price, monthly | C12: 7.99 | D12: $/mo | E12: FACT | F12: D-134 and docs/COMMERCIAL-CORE.md; the catalog charges this.
A13: price_a | B13: Plus list price, annual | C13: 59 | D13: $/yr | E13: FACT | F13: D-134. Effective $4.92/mo.
A14: stud_disc | B14: Average promotional / edu discount on list | C14: 0.1 | D14: % | E14: HYP | F14: No promo program exists. Counsel to review any student-pricing claim.
A15: refund | B15: Refunds + chargebacks, share of billings | C15: 0.033 | D15: % | E15: HYP | F15: Contra-revenue. Refund policy is not yet approved.
A16: organic_start | B16: Organic + campus-led free signups, month 1 | C16: 1200 | D16: users/mo | E16: HYP | F16: No acquisition history. Pre-seasonality trend.
A17: cps | B17: Paid acquisition: cost per free signup | C17: 3 | D17: $ | E17: HYP | F17: Test in paid channels before scaling; student CPI varies widely.
A18: activation | B18: Signups that become monthly-active | C18: 0.6 | D18: % | E18: HYP | F18: Measure with the activation definition in ANALYTICS.md.
A19: free_churn | B19: Monthly churn of active free users | C19: 0.12 | D19: % | E19: HYP | F19: Academic-calendar driven; calibrate on cohorts.
A20: conv | B20: Free-to-paid conversion, monthly, of active free base | C20: 0.0025 | D20: % | E20: HYP | F20: No paying cohort evidenced. Single most sensitive consumer input.
A21: annual_mix | B21: Share of new paid on annual plan | C21: 0.45 | D21: % | E21: HYP
A22: churn_m | B22: Monthly plan churn (per month) | C22: 0.05 | D22: % | E22: HYP | F22: Summer and graduation churn are folded into the average.
A23: renew_a | B23: Annual plan renewal rate at term | C23: 0.55 | D23: % | E23: HYP
A24: iap_share | B24: Student billings through app stores (native apps) | C24: 0.25 | D24: % | E24: PRO | F24: App-store purchase rules for digital subscriptions: platform-policy and counsel review.
A25: iap_fee | B25: App-store commission | C25: 0.15 | D25: % | E25: VENDOR | F25: Assumes a reduced-rate program; verify current store terms.
A26: stripe_pct | B26: Card processing, percent | C26: 0.029 | D26: % | E26: VENDOR | F26: Verify current Stripe pricing and any negotiated rate.
A27: stripe_fix | B27: Card processing, fixed fee per charge | C27: 0.3 | D27: $ | E27: VENDOR | F27: Verify.
A28: Institutional platform
A29: inst_disc | B29: Average realized discount off institutional list | C29: 0.12 | D29: % | E29: POLICY | F29: Within the deal-desk ladder (<=20% needs finance).
A30: rr_i | B30: Gross logo renewal rate at term | C30: 0.88 | D30: % | E30: HYP | F30: No contract has reached term.
A31: expansion | B31: Expansion on retained contract value (modules, bands) | C31: 0.1 | D31: % | E31: HYP | F31: NRR (core) = renewal x (1 + expansion).
A32: pilot_share | B32: Share of full rollout active during a pilot | C32: 0.35 | D32: % | E32: HYP | F32: Pilot is a bounded cohort (D-134: 26 weeks).
A33: bad_debt | B33: Bad debt, share of institutional billings | C33: 0.01 | D33: % | E33: HYP | F33: Accountant to set reserve method.
A34: attach_int | B34: New institutions buying an integration package | C34: 0.4 | D34: % | E34: HYP | F34: SIS/LMS connectors scoped separately (PRICING-AND-PACKAGING.md).
A35: int_fee | B35: Integration package fee | C35: 15000 | D35: $ | E35: HYP
A36: int_hours | B36: Integration package delivery hours | C36: 110 | D36: hours | E36: HYP | F36: Measure on the first integration.
A37: loaded_rate | B37: Loaded implementation cost per hour | C37: 85 | D37: $/hr | E37: HYP | F37: ~$100k salary x 1.22 burden / ~1,430 productive hours.
A38: hrs_per_fte | B38: Billable implementation hours per FTE per month | C38: 110 | D38: hours | E38: HYP
A39: comm_rate | B39: Sales commission on new-logo bookings | C39: 0.08 | D39: % | E39: HYP | F39: Plan not designed; counsel/accountant review of commission accounting.
A40: Add-on streams
A41: ai_start | B41: AI capacity add-on available from month | C41: 20 | D41: month | E41: HYP
...

Sheet Headcount
A1: Hiring plan (gated roles shift by the scenario hiring delay)
A3: ID | B3: Role | C3: Function | D3: FTE | E3: Start month | F3: Base salary | G3: Gated (1 = waits for evidence gate) | H3: P&L placement | I3: Extra (1 = only in full-scope staffing)
A5: GA-1 | B5: CEO / founder | C5: GA | D5: 1 | E5: 1 | F5: 90000 | G5: 0 | H5: G&A | I5: 0
A6: GA-2 | B6: Fractional CFO / controller (0.4 FTE) | C6: GA | D6: 0.4 | E6: 1 | F6: 150000 | G6: 0 | H6: G&A | I6: 0
A7: GA-3 | B7: Compliance and privacy manager | C7: GA | D7: 1 | E7: 9 | F7: 125000 | G7: 0 | H7: G&A | I7: 0
A8: GA-4 | B8: Finance and RevOps manager | C8: GA | D8: 1 | E8: 15 | F8: 120000 | G8: 0 | H8: G&A | I8: 0
A9: GA-5 | B9: Executive operations / people | C9: GA | D9: 1 | E9: 24 | F9: 85000 | G9: 0 | H9: G&A | I9: 0
A10: EN-1 | B10: CTO / co-founder | C10: ENG | D10: 1 | E10: 1 | F10: 110000 | G10: 0 | H10: Engineering | I10: 0
A11: EN-2 | B11: Senior engineers (platform, web) | C11: ENG | D11: 2 | E11: 1 | F11: 150000 | G11: 0 | H11: Engineering | I11: 0
A12: EN-3 | B12: Data / AI engineer | C12: ENG | D12: 1 | E12: 5 | F12: 160000 | G12: 0 | H12: Engineering | I12: 0
A13: EN-4 | B13: Senior engineer | C13: ENG | D13: 1 | E13: 6 | F13: 150000 | G13: 0 | H13: Engineering | I13: 0
A14: EN-5 | B14: Mobile engineer (iOS / Android, offline sync) | C14: ENG | D14: 1 | E14: 9 | F14: 145000 | G14: 0 | H14: Engineering | I14: 0
A15: EN-6 | B15: Senior engineer | C15: ENG | D15: 1 | E15: 13 | F15: 150000 | G15: 0 | H15: Engineering | I15: 0
A16: EN-7 | B16: SRE / DevOps | C16: ENG | D16: 1 | E16: 14 | F16: 150000 | G16: 0 | H16: Engineering | I16: 0
... A74: X-30 | B74: Data / analytics engineer | C74: ENG | D74: 1 | E74: 35 | F74: 160000 | G74: 0 | H74: Engineering | I74: 1

Sheet Schedules
A1: Pipeline schedules by month (month 1 = Jan 2027). Counts are expected values.
A3: ID | B3: Schedule | C3: 1 | D3: 2 | E3: 3 | F3: 4 | G3: 5 | H3: 6 | I3: 7 | J3: 8 | K3: 9 | L3: 10 | M3: 11 | N3: 12 | O3: 13 | P3: 14 | Q3: 15 | R3: 16 | S3: 17 | T3: 18 | U3: 19 | V3: 20 | W3: 21 | X3: 22 | Y3: 23 | Z3: 24 | AA3: 25 | AB3: 26 | AC3: 27 | AD3: 28 | AE3: 29 | AF3: 30 | AG3: 31 | AH3: 32 | AI3: 33 | AJ3: 34 | AK3: 35 | AL3: 36 | AM3: Total
A5: pilot_D | B5: Paid pilot starts, Department (month 1 = gate_pilot) | C5: 0 | D5: 1 | E5: 0 | F5: 0 | G5: 1 | H5: 0 | I5: 0 | J5: 2 | K5: 0 | L5: 0 | M5: 2 | N5: 0 | O5: 0 | P5: 3 | Q5: 0 | R5: 0 | S5: 3 | T5: 0 | U5: 0 | V5: 3 | W5: 0 | X5: 0 | Y5: 4 | Z5: 0 | AA5: 0 | AB5: 4 | AC5: 0 | AD5: 0 | AE5: 4 | AF5: 0 | AG5: 0 | AH5: 5 | AI5: 0 | AJ5: 0 | AK5: 5 | AL5: 0 | AM5: =SUM(C5:AL5) -> 37
A6: pilot_C | B6: Paid pilot starts, Campus (month 1 = gate_pilot) | C6: 0 | D6: 0 | E6: 0 | F6: 0 | G6: 1 | H6: 0 | I6: 0 | J6: 1 | K6: 0 | L6: 0 | M6: 1 | N6: 0 | O6: 0 | P6: 1 | Q6: 0 | R6: 0 | S6: 2 | T6: 0 | U6: 0 | V6: 2 | W6: 0 | X6: 0 | Y6: 2 | Z6: 0 | AA6: 0 | AB6: 2 | AC6: 0 | AD6: 0 | AE6: 3 | AF6: 0 | AG6: 0 | AH6: 3 | AI6: 0 | AJ6: 0 | AK6: 3 | AL6: 0 | AM6: =SUM(C6:AL6) -> 21
A7: pilot_Y | B7: Paid pilot starts, System (month 1 = gate_ent) | C7: 0 | D7: 0 | E7: 0 | F7: 0 | G7: 1 | H7: 0 | I7: 0 | J7: 0 | K7: 0 | L7: 0 | M7: 1 | N7: 0 | O7: 0 | P7: 1 | Q7: 0 | R7: 0 | S7: 1 | T7: 0 | U7: 0 | V7: 1 | W7: 0 | X7: 0 | Y7: 1 | Z7: 0 | AA7: 0 | AB7: 1 | AC7: 0 | AD7: 0 | AE7: 1 | AF7: 0 | AG7: 0 | AH7: 1 | AI7: 0 | AJ7: 0 | AK7: 1 | AL7: 0 | AM7: =SUM(C7:AL7) -> 10
A8: direct_D | B8: Direct annual starts, Department (month 1 = gate_direct) | C8: 0 | D8: 1 | E8: 0 | F8: 0 | G8: 1 | H8: 0 | I8: 0 | J8: 2 | K8: 0 | L8: 0 | M8: 2 | N8: 0 | O8: 0 | P8: 3 | Q8: 0 | R8: 0 | S8: 3 | T8: 0 | U8: 0 | V8: 3 | W8: 0 | X8: 0 | Y8: 3 | Z8: 0 | AA8: 0 | AB8: 3 | AC8: 0 | AD8: 0 | AE8: 3 | AF8: 0 | AG8: 0 | AH8: 3 | AI8: 0 | AJ8: 0 | AK8: 3 | AL8: 0 | AM8: =SUM(C8:AL8) -> 30
A9: direct_C | B9: Direct annual starts, Campus (month 1 = gate_direct) | C9: 0 | D9: 0 | E9: 0 | F9: 0 | G9: 1 | H9: 0 | I9: 0 | J9: 1 | K9: 0 | L9: 0 | M9: 1 | N9: 0 | O9: 0 | P9: 2 | Q9: 0 | R9: 0 | S9: 2 | T9: 0 | U9: 0 | V9: 2 | W9: 0 | X9: 0 | Y9: 2 | Z9: 0 | AA9: 0 | AB9: 2 | AC9: 0 | AD9: 0 | AE9: 2 | AF9: 0 | AG9: 0 | AH9: 2 | AI9: 0 | AJ9: 0 | AK9: 2 | AL9: 0 | AM9: =SUM(C9:AL9) -> 19
A10: direct_Y | B10: Direct annual starts, System (month 1 = gate_ent) | C10: 0 | D10: 0 | E10: 0 | F10: 0 | G10: 0 | H10: 0 | I10: 0 | J10: 0 | K10: 0 | L10: 0 | M10: 1 | N10: 0 | O10: 0 | P10: 1 | Q10: 0 | R10: 0 | S10: 1 | T10: 0 | U10: 0 | V10: 1 | W10: 0 | X10: 0 | Y10: 1 | Z10: 0 | AA10: 0 | AB10: 1 | AC10: 0 | AD10: 0 | AE10: 1 | AF10: 0 | AG10: 0 | AH10: 1 | AI10: 0 | AJ10: 0 | AK10: 1 | AL10: 0 | AM10: =SUM(C10:AL10) -> 9
A11: dp_D | B11: Unpaid design-partner pilot starts, Department (absolute month) | C11: 0 | D11: 0 | E11: 0 | F11: 0 | G11: 1 | H11: 0 | I11: 0 | J11: 0 | K11: 0 | L11: 0 | M11: 0 | N11: 0 | O11: 0 | P11: 0 | Q11: 0 | R11: 0 | S11: 0 | T11: 0 | U11: 0 | V11: 0 | W11: 0 | X11: 0 | Y11: 0 | Z11: 0 | AA11: 0 | AB11: 0 | AC11: 0 | AD11: 0 | AE11: 0 | AF11: 0 | AG11: 0 | AH11: 0 | AI11: 0 | AJ11: 0 | AK11: 0 | AL11: 0 | AM11: =SUM(C11:AL11) -> 1
A12: dp_C | B12: Unpaid design-partner pilot starts, Campus (absolute month) | C12: 0 | D12: 0 | E12: 0 | F12: 0 | G12: 0 | H12: 0 | I12: 0 | J12: 1 | K12: 0 | L12: 0 | M12: 0 | N12: 0 | O12: 0 | P12: 0 | Q12: 0 | R12: 0 | S12: 0 | T12: 0 | U12: 0 | V12: 0 | W12: 0 | X12: 0 | Y12: 0 | Z12: 0 | AA12: 0 | AB12: 0 | AC12: 0 | AD12: 0 | AE12: 0 | AF12: 0 | AG12: 0 | AH12: 0 | AI12: 0 | AJ12: 0 | AK12: 0 | AL12: 0 | AM12: =SUM(C12:AL12) -> 1
A13: dp_Y | B13: Unpaid design-partner pilot starts, System (absolute month) | C13: 0 | D13: 0 | E13: 0 | F13: 0 | G13: 0 | H13: 0 | I13: 0 | J13: 0 | K13: 0 | L13: 0 | M13: 0 | N13: 0 | O13: 0 | P13: 0 | Q13: 0 | R13: 0 | S13: 0 | T13: 0 | U13: 0 | V13: 0 | W13: 0 | X13: 0 | Y13: 0 | Z13: 0 | AA13: 0 | AB13: 0 | AC13: 0 | AD13: 0 | AE13: 0 | AF13: 0 | AG13: 0 | AH13: 0 | AI13: 0 | AJ13: 0 | AK13: 0 | AL13: 0 | AM13: =SUM(C13:AL13) -> 0
A14: career_adds | B14: Employer accounts added (absolute month) | C14: 0 | D14: 0 | E14: 0 | F14: 0 | G14: 0 | H14: 0 | I14: 0 | J14: 0 | K14: 0 | L14: 0 | M14: 0 | N14: 0 | O14: 0 | P14: 0 | Q14: 0 | R14: 0 | S14: 0 | T14: 0 | U14: 0 | V14: 0 | W14: 0 | X14: 0 | Y14: 0 | Z14: 0 | AA14: 3 | AB14: 3 | AC14: 3 | AD14: 3 | AE14: 3 | AF14: 3 | AG14: 6 | AH14: 6 | AI14: 6 | AJ14: 6 | AK14: 6 | AL14: 6 | AM14: =SUM(C14:AL14) -> 54

Sheet Cons
A1: Scenario 1: Conservative
A2: All cells are formulas on Assumptions, Headcount, Schedules and the scenario parameters below.
A3: Scenario parameters (linked to Scenarios sheet)
A4: Organic student acquisition multiplier | B4: x | C4: =Scenarios!C4 -> 0.6
A5: Free-to-paid conversion multiplier | B5: x | C5: =Scenarios!C5 -> 0.8
A6: Churn multiplier (students and institutions) | B6: x | C6: =Scenarios!C6 -> 1.25
A7: Pilot and direct-deal volume multiplier | B7: x | C7: =Scenarios!C7 -> 0.6
A8: Pilot-to-annual conversion multiplier | B8: x | C8: =Scenarios!C8 -> 0.8
A9: Institutional gates slip by (months) | B9: months | C9: =Scenarios!C9 -> 2
A10: Institutional price realization multiplier | B10: x | C10: =Scenarios!C10 -> 0.95
A11: Paid acquisition cost multiplier | B11: x | C11: =Scenarios!C11 -> 1.25
A12: AI unit cost multiplier (price or model-mix shift) | B12: x | C12: =Scenarios!C12 -> 1
A13: AI usage multiplier (requests per user) | B13: x | C13: =Scenarios!C13 -> 1
A14: Incident switch (1 = on) | B14: 0/1 | C14: =Scenarios!C14 -> 0
A15: Delay for gated hires (months) | B15: months | C15: =Scenarios!C15 -> 0
A16: Full-scope staffing switch (1 = include the CTO-pack staffing roles) | B16: 0/1 | C16: =Scenarios!C16 -> 0
A18: Month | C18: 1 | D18: 2 | E18: 3 | F18: 4 | G18: 5 | H18: 6 | I18: 7 | J18: 8 | K18: 9 | L18: 10 | M18: 11 | N18: 12 | O18: 13 | P18: 14 | Q18: 15 | R18: 16 | S18: 17 | T18: 18 | U18: 19 | V18: 20 | W18: 21 | X18: 22 | Y18: 23 | Z18: 24 | AA18: 25 | AB18: 26 | AC18: 27 | AD18: 28 | AE18: 29 | AF18: 30 | AG18: 31 | AH18: 32 | AI18: 33 | AJ18: 34 | AK18: 35 | AL18: 36 | AN18: Year 1 | AO18: Year 2 | AP18: Year 3
A19: Calendar | C19: Jan-27 | D19: Feb-27 | E19: Mar-27 | F19: Apr-27 | G19: May-27 | H19: Jun-27 | I19: Jul-27 | J19: Aug-27 | K19: Sep-27 | L19: Oct-27 | M19: Nov-27 | N19: Dec-27 | O19: Jan-28 | P19: Feb-28 | Q19: Mar-28 | R19: Apr-28 | S19: May-28 | T19: Jun-28 | U19: Jul-28 | V19: Aug-28 | W19: Sep-28 | X19: Oct-28 | Y19: Nov-28 | Z19: Dec-28 | AA19: Jan-29 | AB19: Feb-29 | AC19: Mar-29 | AD19: Apr-29 | AE19: May-29 | AF19: Jun-29 | AG19: Jul-29 | AH19: Aug-29 | AI19: Sep-29 | AJ19: Oct-29 | AK19: Nov-29 | AL19: Dec-29 | AN19: 2027 | AO19: 2028 | AP19: 2029
A20: Year | C20: =INT((C18-1)/12)+1 -> 1 | D20: =INT((D18-1)/12)+1 -> 1 | E20: =INT((E18-1)/12)+1 -> 1 | F20: =INT((F18-1)/12)+1 -> 1 | G20: =INT((G18-1)/12)+1 -> 1 | H20: =INT((H18-1)/12)+1 -> 1 | I20: =INT((I18-1)/12)+1 -> 1 | J20: =INT((J18-1)/12)+1 -> 1 | ... AL20: =INT((AL18-1)/12)+1 -> 3
A21: Month of year | C21: =MOD(C18-1,12)+1 -> 1 | D21: =MOD(D18-1,12)+1 -> 2 | E21: =MOD(E18-1,12)+1 -> 3 | F21: =MOD(F18-1,12)+1 -> 4 | G21: =MOD(G18-1,12)+1 -> 5 | H21: =MOD(H18-1,12)+1 -> 6 | I21: =MOD(I18-1,12)+1 -> 7 | J21: =MOD(J18-1,12)+1 -> 8 | ... AL21: =MOD(AL18-1,12)+1 -> 12
A23: Student subscription: funnel and subscribers
A24: Organic signup trend (pre-seasonality) | B24: users | C24: =IF((C$18=1),Assumptions!$C$16,(0*(1+Assumptions!$C$133))) -> 1200 | D24: =IF((D$18=1),Assumptions!$C$16,(C24*(1+Assumptions!$C$133))) -> 1272 | E24: =IF((E$18=1),Assumptions!$C$16,(D24*(1+Assumptions!$C$133))) -> 1348.32 | F24: =IF((F$18=1),Assumptions!$C$16,(E24*(1+Assumptions!$C$133))) -> 1429.2192 | G24: =IF((G$18=1),Assumptions!$C$16,(F24*(1+Assumptions!$C$133))) -> 1514.9724 | H24: =IF((H$18=1),Assumptions!$C$16,(G24*(1+Assumptions!$C$133))) -> 1605.8707 | I24: =IF((I$18=1),Assumptions!$C$16,(H24*(1+Assumptions!$C$133))) -> 1702.2229 | J24: =IF((J$18=1),Assumptions!$C$16,(I24*(1+Assumptions!$C$133))) -> 1804.3563 | K24: =IF((K$18=1),Assumptions!$C$16,(J24*(1+Assumptions!$C$133))) -> 1912.6177 | ... N24: =IF((N$18=1),Assumptions!$C$16,(M24*(1+Assumptions!$C$133))) -> 2277.9583 | O24: =IF((O$18=1),Assumptions!$C$16,(N24*(1+Assumptions!$D$133))) -> 2369.0766 | P24: =IF((P$18=1),Assumptions!$C$16,(O24*(1+Assumptions!$D$133))) -> 2463.8397 | Q24: =IF((Q$18=1),Assumptions!$C$16,(P24*(1+Assumptions!$D$133))) -> 2562.3933 | R24: =IF((R$18=1),Assumptions!$C$16,(Q24*(1+Assumptions!$D$133))) -> 2664.889 | S24: =IF((S$18=1),Assumptions!$C$16,(R24*(1+Assumptions!$D$133))) -> 2771.4845 | T24: =IF((T$18=1),Assumptions!$C$16,(S24*(1+Assumptions!$D$133))) -> 2882.3439 | U24: =IF((U$18=1),Assumptions!$C$16,(T24*(1+Assumptions!$D$133))) -> 2997.6377 | V24: =IF((V$18=1),Assumptions!$C$16,(U24*(1+Assumptions!$D$133))) -> 3117.5432 | ... Z24: =IF((Z$18=1),Assumptions!$C$16,(Y24*(1+Assumptions!$D$133))) -> 3647.0846 | AA24: =IF((AA$18=1),Assumptions!$C$16,(Z24*(1+Assumptions!$E$133))) -> 3738.2617 | AB24: =IF((AB$18=1),Assumptions!$C$16,(AA24*(1+Assumptions!$E$133))) -> 3831.7182 | AC24: =IF((AC$18=1),Assumptions!$C$16,(AB24*(1+Assumptions!$E$133))) -> 3927.5112 | AD24: =IF((AD$18=1),Assumptions!$C$16,(AC24*(1+Assumptions!$E$133))) -> 4025.699 | AE24: =IF((AE$18=1),Assumptions!$C$16,(AD24*(1+Assumptions!$E$133))) -> 4126.3415 | AF24: =IF((AF$18=1),Assumptions!$C$16,(AE24*(1+Assumptions!$E$133))) -> 4229.5 | AG24: =IF((AG$18=1),Assumptions!$C$16,(AF24*(1+Assumptions!$E$133))) -> 4335.2375 | AH24: =IF((AH$18=1),Assumptions!$C$16,(AG24*(1+Assumptions!$E$133))) -> 4443.6184 | ... AL24: =IF((AL$18=1),Assumptions!$C$16,(AK24*(1+Assumptions!$E$133))) -> 4904.9233
A25: Organic + campus-led free signups | B25: users | C25: =(((C24*INDEX(Assumptions!$C$167:$C$178,C$21))*$C$4)*IF((C$18<Assumptions!$C$5),Assumptions!$C$6,1)) -> 234 | D25: =(((D24*INDEX(Assumptions!$C$167:$C$178,D$21))*$C$4)*IF((D$18<Assumptions!$C$5),Assumptions!$C$6,1)) -> 209.88 | E25: =(((E24*INDEX(Assumptions!$C$167:$C$178,E$21))*$C$4)*IF((E$18<Assumptions!$C$5),Assumptions!$C$6,1)) -> 182.0232 | F25: =(((F24*INDEX(Assumptions!$C$167:$C$178,F$21))*$C$4)*IF((F$18<Assumptions!$C$5),Assumptions!$C$6,1)) -> 171.5063 | G25: =(((G24*INDEX(Assumptions!$C$167:$C$178,G$21))*$C$4)*IF((G$18<Assumptions!$C$5),Assumptions!$C$6,1)) -> 136.34751 | H25: =(((H24*INDEX(Assumptions!$C$167:$C$178,H$21))*$C$4)*IF((H$18<Assumptions!$C$5),Assumptions!$C$6,1)) -> 120.4403 | I25: =(((I24*INDEX(Assumptions!$C$167:$C$178,I$21))*$C$4)*IF((I$18<Assumptions!$C$5),Assumptions!$C$6,1)) -> 178.73341 | J25: =(((J24*INDEX(Assumptions!$C$167:$C$178,J$21))*$C$4)*IF((J$18<Assumptions!$C$5),Assumptions!$C$6,1)) -> 433.04551 | ... AL25: =(((AL24*INDEX(Assumptions!$C$167:$C$178,AL$21))*$C$4)*IF((AL$18<Assumptions!$C$5),Assumptions!$C$6,1)) -> 2060.0678 | AN25: =SUM(C25:N25) -> 3046.2028 | AO25: =SUM(O25:Z25) -> 21403.695 | AP25: =SUM(AA25:AL25) -> 30983.447
A26: Paid-acquisition free signups | B26: users | C26: =IF((C$18>=Assumptions!$C$5),(Assumptions!$C$134/(Assumptions!$C$17*$C$11)),0) -> 0 | D26: =IF((D$18>=Assumptions!$C$5),(Assumptions!$C$134/(Assumptions!$C$17*$C$11)),0) -> 0 | E26: =IF((E$18>=Assumptions!$C$5),(Assumptions!$C$134/(Assumptions!$C$17*$C$11)),0) -> 0 | F26: =IF((F$18>=Assumptions!$C$5),(Assumptions!$C$134/(Assumptions!$C$17*$C$11)),0) -> 0 | G26: =IF((G$18>=Assumptions!$C$5),(Assumptions!$C$134/(Assumptions!$C$17*$C$11)),0) -> 0 | H26: =IF((H$18>=Assumptions!$C$5),(Assumptions!$C$134/(Assumptions!$C$17*$C$11)),0) -> 0 | I26: =IF((I$18>=Assumptions!$C$5),(Assumptions!$C$134/(Assumptions!$C$17*$C$11)),0) -> 0 | J26: =IF((J$18>=Assumptions!$C$5),(Assumptions!$C$134/(Assumptions!$C$17*$C$11)),0) -> 0 | ... N26: =IF((N$18>=Assumptions!$C$5),(Assumptions!$C$134/(Assumptions!$C$17*$C$11)),0) -> 0 | O26: =IF((O$18>=Assumptions!$C$5),(Assumptions!$D$134/(Assumptions!$C$17*$C$11)),0) -> 800 | P26: =IF((P$18>=Assumptions!$C$5),(Assumptions!$D$134/(Assumptions!$C$17*$C$11)),0) -> 800 | Q26: =IF((Q$18>=Assumptions!$C$5),(Assumptions!$D$134/(Assumptions!$C$17*$C$11)),0) -> 800 | R26: =IF((R$18>=Assumptions!$C$5),(Assumptions!$D$134/(Assumptions!$C$17*$C$11)),0) -> 800 | S26: =IF((S$18>=Assumptions!$C$5),(Assumptions!$D$134/(Assumptions!$C$17*$C$11)),0) -> 800 | T26: =IF((T$18>=Assumptions!$C$5),(Assumptions!$D$134/(Assumptions!$C$17*$C$11)),0) -> 800 | U26: =IF((U$18>=Assumptions!$C$5),(Assumptions!$D$134/(Assumptions!$C$17*$C$11)),0) -> 800 | V26: =IF((V$18>=Assumptions!$C$5),(Assumptions!$D$134/(Assumptions!$C$17*$C$11)),0) -> 800 | ... Z26: =IF((Z$18>=Assumptions!$C$5),(Assumptions!$D$134/(Assumptions!$C$17*$C$11)),0) -> 800 | AA26: =IF((AA$18>=Assumptions!$C$5),(Assumptions!$E$134/(Assumptions!$C$17*$C$11)),0) -> 1333.3333 | AB26: =IF((AB$18>=Assumptions!$C$5),(Assumptions!$E$134/(Assumptions!$C$17*$C$11)),0) -> 1333.3333 | AC26: =IF((AC$18>=Assumptions!$C$5),(Assumptions!$E$134/(Assumptions!$C$17*$C$11)),0) -> 1333.3333 | AD26: =IF((AD$18>=Assumptions!$C$5),(Assumptions!$E$134/(Assumptions!$C$17*$C$11)),0) -> 1333.3333 | AE26: =IF((AE$18>=Assumptions!$C$5),(Assumptions!$E$134/(Assumptions!$C$17*$C$11)),0) -> 1333.3333 | AF26: =IF((AF$18>=Assumptions!$C$5),(Assumptions!$E$134/(Assumptions!$C$17*$C$11)),0) -> 1333.3333 | AG26: =IF((AG$18>=Assumptions!$C$5),(Assumptions!$E$134/(Assumptions!$C$17*$C$11)),0) -> 1333.3333 | AH26: =IF((AH$18>=Assumptions!$C$5),(Assumptions!$E$134/(Assumptions!$C$17*$C$11)),0) -> 1333.3333 | ... AL26: =IF((AL$18>=Assumptions!$C$5),(Assumptions!$E$134/(Assumptions!$C$17*$C$11)),0) -> 1333.3333 | AN26: =SUM(C26:N26) -> 0 | AO26: =SUM(O26:Z26) -> 9600 | AP26: =SUM(AA26:AL26) -> 16000
A27: New monthly-active free users | B27: users | C27: =((C25+C26)*Assumptions!$C$18) -> 140.4 | D27: =((D25+D26)*Assumptions!$C$18) -> 125.928 | E27: =((E25+E26)*Assumptions!$C$18) -> 109.21392 | F27: =((F25+F26)*Assumptions!$C$18) -> 102.90378 | G27: =((G25+G26)*Assumptions!$C$18) -> 81.808507 | H27: =((H25+H26)*Assumptions!$C$18) -> 72.264181 | I27: =((I25+I26)*Assumptions!$C$18) -> 107.24004 | J27: =((J25+J26)*Assumptions!$C$18) -> 259.82731 | ... AL27: =((AL25+AL26)*Assumptions!$C$18) -> 2036.0407 | AN27: =SUM(C27:N27) -> 1827.7217 | AO27: =SUM(O27:Z27) -> 18602.217 | AP27: =SUM(AA27:AL27) -> 28190.068
A28: New paying subscribers (conversions) | B28: users | C28: =IF((C$18>=Assumptions!$C$5),((Assumptions!$C$20*$C$5)*0),0) -> 0 | D28: =IF((D$18>=Assumptions!$C$5),((Assumptions!$C$20*$C$5)*C29),0) -> 0 | E28: =IF((E$18>=Assumptions!$C$5),((Assumptions!$C$20*$C$5)*D29),0) -> 0 | F28: =IF((F$18>=Assumptions!$C$5),((Assumptions!$C$20*$C$5)*E29),0) -> 0 | G28: =IF((G$18>=Assumptions!$C$5),((Assumptions!$C$20*$C$5)*F29),0) -> 0 | H28: =IF((H$18>=Assumptions!$C$5),((Assumptions!$C$20*$C$5)*G29),0) -> 0 | I28: =IF((I$18>=Assumptions!$C$5),((Assumptions!$C$20*$C$5)*H29),0) -> 0 | J28: =IF((J$18>=Assumptions!$C$5),((Assumptions!$C$20*$C$5)*I29),0) -> 0 | K28: =IF((K$18>=Assumptions!$C$5),((Assumptions!$C$20*$C$5)*J29),0) -> 0 | ... AL28: =IF((AL$18>=Assumptions!$C$5),((Assumptions!$C$20*$C$5)*AK29),0) -> 36.09349 | AN28: =SUM(C28:N28) -> 0 | AO28: =SUM(O28:Z28) -> 147.26145 | AP28: =SUM(AA28:AL28) -> 344.45874
A29: Active free users (end of month) | B29: users | C29: =MAX(0,(((0*(1-Assumptions!$C$19))+C27)-C28)) -> 140.4 | D29: =MAX(0,(((C29*(1-Assumptions!$C$19))+D27)-D28)) -> 249.48 | E29: =MAX(0,(((D29*(1-Assumptions!$C$19))+E27)-E28)) -> 328.75632 | F29: =MAX(0,(((E29*(1-Assumptions!$C$19))+F27)-F28)) -> 392.20934 | G29: =MAX(0,(((F29*(1-Assumptions!$C$19))+G27)-G28)) -> 426.95273 | H29: =MAX(0,(((G29*(1-Assumptions!$C$19))+H27)-H28)) -> 447.98258 | I29: =MAX(0,(((H29*(1-Assumptions!$C$19))+I27)-I28)) -> 501.46472 | J29: =MAX(0,(((I29*(1-Assumptions!$C$19))+J27)-J28)) -> 701.11626 | K29: =MAX(0,(((J29*(1-Assumptions!$C$19))+K27)-K28)) -> 926.82638 | ... AL29: =MAX(0,(((AK29*(1-Assumptions!$C$19))+AL27)-AL28)) -> 17881.083 | AN29: =N29 -> 1083.7294 | AO29: =Z29 -> 10702.998 | AP29: =AL29 -> 17881.083
A30: Incident: extra monthly paid churn | B30: % | C30: =IF(AND(($C$14=1),(C$18>=(Assumptions!$C$106+1)),(C$18<=(Assumptions!$C$106+3))),Assumptions!$C$115,0) -> 0 | D30: =IF(AND(($C$14=1),(D$18>=(Assumptions!$C$106+1)),(D$18<=(Assumptions!$C$106+3))),Assumptions!$C$115,0) -> 0 | E30: =IF(AND(($C$14=1),(E$18>=(Assumptions!$C$106+1)),(E$18<=(Assumptions!$C$106+3))),Assumptions!$C$115,0) -> 0 | F30: =IF(AND(($C$14=1),(F$18>=(Assumptions!$C$106+1)),(F$18<=(Assumptions!$C$106+3))),Assumptions!$C$115,0) -> 0 | G30: =IF(AND(($C$14=1),(G$18>=(Assumptions!$C$106+1)),(G$18<=(Assumptions!$C$106+3))),Assumptions!$C$115,0) -> 0 | H30: =IF(AND(($C$14=1),(H$18>=(Assumptions!$C$106+1)),(H$18<=(Assumptions!$C$106+3))),Assumptions!$C$115,0) -> 0 | I30: =IF(AND(($C$14=1),(I$18>=(Assumptions!$C$106+1)),(I$18<=(Assumptions!$C$106+3))),Assumptions!$C$115,0) -> 0 | J30: =IF(AND(($C$14=1),(J$18>=(Assumptions!$C$106+1)),(J$18<=(Assumptions!$C$106+3))),Assumptions!$C$115,0) -> 0 | ... AL30: =IF(AND(($C$14=1),(AL$18>=(Assumptions!$C$106+1)),(AL$18<=(Assumptions!$C$106+3))),Assumptions!$C$115,0) -> 0
A31: Effective monthly plan churn | B31: % | C31: =MIN(1,((Assumptions!$C$22*$C$6)+C30)) -> 0.0625 | D31: =MIN(1,((Assumptions!$C$22*$C$6)+D30)) -> 0.0625 | E31: =MIN(1,((Assumptions!$C$22*$C$6)+E30)) -> 0.0625 | F31: =MIN(1,((Assumptions!$C$22*$C$6)+F30)) -> 0.0625 | G31: =MIN(1,((Assumptions!$C$22*$C$6)+G30)) -> 0.0625 | H31: =MIN(1,((Assumptions!$C$22*$C$6)+H30)) -> 0.0625 | I31: =MIN(1,((Assumptions!$C$22*$C$6)+I30)) -> 0.0625 | J31: =MIN(1,((Assumptions!$C$22*$C$6)+J30)) -> 0.0625 | ... AL31: =MIN(1,((Assumptions!$C$22*$C$6)+AL30)) -> 0.0625
A32: New monthly-plan subscribers | B32: users | C32: =(C28*(1-Assumptions!$C$21)) -> 0 | D32: =(D28*(1-Assumptions!$C$21)) -> 0 | E32: =(E28*(1-Assumptions!$C$21)) -> 0 | F32: =(F28*(1-Assumptions!$C$21)) -> 0 | G32: =(G28*(1-Assumptions!$C$21)) -> 0 | H32: =(H28*(1-Assumptions!$C$21)) -> 0 | I32: =(I28*(1-Assumptions!$C$21)) -> 0 | J32: =(J28*(1-Assumptions!$C$21)) -> 0 | ... AL32: =(AL28*(1-Assumptions!$C$21)) -> 19.85142 | AN32: =SUM(C32:N32) -> 0 | AO32: =SUM(O32:Z32) -> 80.9938 | AP32: =SUM(AA32:AL32) -> 189.45231
A33: New annual-plan subscribers | B33: users | C33: =(C28*Assumptions!$C$21) -> 0 | D33: =(D28*Assumptions!$C$21) -> 0 | E33: =(E28*Assumptions!$C$21) -> 0 | F33: =(F28*Assumptions!$C$21) -> 0 | G33: =(G28*Assumptions!$C$21) -> 0 | H33: =(H28*Assumptions!$C$21) -> 0 | I33: =(I28*Assumptions!$C$21) -> 0 | J33: =(J28*Assumptions!$C$21) -> 0 | ... AL33: =(AL28*Assumptions!$C$21) -> 16.242071 | AN33: =SUM(C33:N33) -> 0 | AO33: =SUM(O33:Z33) -> 66.267654 | AP33: =SUM(AA33:AL33) -> 155.00643
A34: Monthly-plan subscribers (end) | B34: users | C34: =((0*(1-C31))+C32) -> 0 | D34: =((C34*(1-D31))+D32) -> 0 | E34: =((D34*(1-E31))+E32) -> 0 | F34: =((E34*(1-F31))+F32) -> 0 | G34: =((F34*(1-G31))+G32) -> 0 | H34: =((G34*(1-H31))+H32) -> 0 | I34: =((H34*(1-I31))+I32) -> 0 | J34: =((I34*(1-J31))+J32) -> 0 | K34: =((J34*(1-K31))+K32) -> 0 | ... AL34: =((AK34*(1-AL31))+AL32) -> 170.29524 | AN34: =N34 -> 0 | AO34: =Z34 -> 64.191711 | AP34: =AL34 -> 170.29524
